<?xml version="1.0"?>
<robot name="TIAGo Steel" xmlns:xacro="http://ros.org/wiki/xacro">
  <link name="base_link">
    <visual>
      <origin xyz="0 0 0.06" rpy="3.1407962 0 0"/>
      <geometry>
        <cylinder radius="0.265" length="0.276"/>
      </geometry>
    </visual>
    <collision>
      <origin xyz="0 0 0.06" rpy="3.1407962 0 0"/>
      <geometry>
        <cylinder radius="0.265" length="0.276"/>
      </geometry>
    </collision>
    <visual>
      <origin xyz="-0.201 0.1062 0.28" rpy="3.1407962 0 0"/>
      <geometry>
        <cylinder radius="0.007" length="0.173"/>
      </geometry>
    </visual>
    <collision>
      <origin xyz="-0.201 0.1062 0.28" rpy="3.1407962 0 0"/>
      <geometry>
        <cylinder radius="0.007" length="0.173"/>
      </geometry>
    </collision>
    <visual>
      <origin xyz="-0.201 -0.1062 0.28" rpy="3.1407962 0 0"/>
      <geometry>
        <cylinder radius="0.007" length="0.173"/>
      </geometry>
    </visual>
    <collision>
      <origin xyz="-0.201 -0.1062 0.28" rpy="3.1407962 0 0"/>
      <geometry>
        <cylinder radius="0.007" length="0.173"/>
      </geometry>
    </collision>
  </link>
  <joint name="hingejoint_6023" type="continuous">
    <parent link="base_link"/>
    <child link="caster_back_left_1_link"/>
    <axis xyz="0 0 1"/>
    <origin xyz="-0.1735 0.102 -0.0335" rpy="0 0 0"/>
  </joint>
  <link name="caster_back_left_1_link">
    <visual>
      <origin xyz="-0.003 0 -0.022" rpy="0 0 0"/>
      <geometry>
        <box size="0.036 0.032 0.04"/>
      </geometry>
    </visual>
    <collision>
      <origin xyz="-0.003 0 -0.022" rpy="0 0 0"/>
      <geometry>
        <box size="0.036 0.032 0.04"/>
      </geometry>
    </collision>
  </link>
  <joint name="hingejoint_6026" type="continuous">
    <parent link="caster_back_left_1_link"/>
    <child link="caster_back_left_2_link"/>
    <axis xyz="0 -3.6732051e-06 1"/>
    <origin xyz="-0.016 0 -0.04" rpy="-1.5708 0 0"/>
  </joint>
  <link name="caster_back_left_2_link">
    <visual>
      <origin xyz="0 0 0" rpy="3.1415923 0 0"/>
      <geometry>
        <cylinder radius="0.025" length="0.015"/>
      </geometry>
    </visual>
    <collision>
      <origin xyz="0 0 0" rpy="3.1415923 0 0"/>
      <geometry>
        <cylinder radius="0.025" length="0.015"/>
      </geometry>
    </collision>
  </link>
  <joint name="hingejoint_5988" type="continuous">
    <parent link="base_link"/>
    <child link="caster_back_right_1_link"/>
    <axis xyz="0 0 1"/>
    <origin xyz="-0.1735 -0.102 -0.0335" rpy="0 0 0"/>
  </joint>
  <link name="caster_back_right_1_link">
    <visual>
      <origin xyz="-0.003 0 -0.022" rpy="0 0 0"/>
      <geometry>
        <box size="0.036 0.032 0.04"/>
      </geometry>
    </visual>
    <collision>
      <origin xyz="-0.003 0 -0.022" rpy="0 0 0"/>
      <geometry>
        <box size="0.036 0.032 0.04"/>
      </geometry>
    </collision>
  </link>
  <joint name="hingejoint_5991" type="continuous">
    <parent link="caster_back_right_1_link"/>
    <child link="caster_back_right_2_link"/>
    <axis xyz="0 -3.6732051e-06 1"/>
    <origin xyz="-0.016 0 -0.04" rpy="-1.5708 0 0"/>
  </joint>
  <link name="caster_back_right_2_link">
    <visual>
      <origin xyz="0 0 0" rpy="3.1415923 0 0"/>
      <geometry>
        <cylinder radius="0.025" length="0.015"/>
      </geometry>
    </visual>
    <collision>
      <origin xyz="0 0 0" rpy="3.1415923 0 0"/>
      <geometry>
        <cylinder radius="0.025" length="0.015"/>
      </geometry>
    </collision>
  </link>
  <joint name="hingejoint_5953" type="continuous">
    <parent link="base_link"/>
    <child link="caster_front_left_1_link"/>
    <axis xyz="0 0 1"/>
    <origin xyz="0.1695 0.102 -0.0335" rpy="0 0 0"/>
  </joint>
  <link name="caster_front_left_1_link">
    <visual>
      <origin xyz="-0.003 0 -0.022" rpy="0 0 0"/>
      <geometry>
        <box size="0.036 0.032 0.04"/>
      </geometry>
    </visual>
    <collision>
      <origin xyz="-0.003 0 -0.022" rpy="0 0 0"/>
      <geometry>
        <box size="0.036 0.032 0.04"/>
      </geometry>
    </collision>
  </link>
  <joint name="hingejoint_5956" type="continuous">
    <parent link="caster_front_left_1_link"/>
    <child link="caster_front_left_2_link"/>
    <axis xyz="0 -3.6732051e-06 1"/>
    <origin xyz="-0.016 0 -0.04" rpy="-1.5708 0 0"/>
  </joint>
  <link name="caster_front_left_2_link">
    <visual>
      <origin xyz="0 0 0" rpy="3.1415923 0 0"/>
      <geometry>
        <cylinder radius="0.025" length="0.015"/>
      </geometry>
    </visual>
    <collision>
      <origin xyz="0 0 0" rpy="3.1415923 0 0"/>
      <geometry>
        <cylinder radius="0.025" length="0.015"/>
      </geometry>
    </collision>
  </link>
  <joint name="hingejoint_5918" type="continuous">
    <parent link="base_link"/>
    <child link="caster_front_right_1_link"/>
    <axis xyz="0 0 1"/>
    <origin xyz="0.1695 -0.102 -0.0335" rpy="0 0 0"/>
  </joint>
  <link name="caster_front_right_1_link">
    <visual>
      <origin xyz="-0.003 0 -0.022" rpy="0 0 0"/>
      <geometry>
        <box size="0.036 0.032 0.04"/>
      </geometry>
    </visual>
    <collision>
      <origin xyz="-0.003 0 -0.022" rpy="0 0 0"/>
      <geometry>
        <box size="0.036 0.032 0.04"/>
      </geometry>
    </collision>
  </link>
  <joint name="hingejoint_5921" type="continuous">
    <parent link="caster_front_right_1_link"/>
    <child link="caster_front_right_2_link"/>
    <axis xyz="0 -3.6732051e-06 1"/>
    <origin xyz="-0.016 0 -0.04" rpy="-1.5708 0 0"/>
  </joint>
  <link name="caster_front_right_2_link">
    <visual>
      <origin xyz="0 0 0" rpy="-3.141589 0 0"/>
      <geometry>
        <cylinder radius="0.025" length="0.015"/>
      </geometry>
    </visual>
    <collision>
      <origin xyz="0 0 0" rpy="-3.141589 0 0"/>
      <geometry>
        <cylinder radius="0.025" length="0.015"/>
      </geometry>
    </collision>
  </link>
  <joint name="wheel_left_joint" type="continuous">
    <parent link="base_link"/>
    <child link="wheel_left_link"/>
    <axis xyz="0 -3.6732051e-06 -1"/>
    <limit effort="10" velocity="10.1523"/>
    <origin xyz="0 0.2022 0" rpy="1.5708 0 0"/>
  </joint>
  <link name="wheel_left_link">
    <visual>
      <origin xyz="0 7.34641e-10 0.0002" rpy="-3.141589 0 0"/>
      <geometry>
        <cylinder radius="0.0985" length="0.04"/>
      </geometry>
    </visual>
    <collision>
      <origin xyz="0 7.34641e-10 0.0002" rpy="-3.141589 0 0"/>
      <geometry>
        <cylinder radius="0.0985" length="0.04"/>
      </geometry>
    </collision>
  </link>
  <joint name="wheel_right_joint" type="continuous">
    <parent link="base_link"/>
    <child link="wheel_right_link"/>
    <axis xyz="0 -3.6732051e-06 -1"/>
    <limit effort="10" velocity="10.1523"/>
    <origin xyz="0 -0.2022 0.0002" rpy="1.5708 0 0"/>
  </joint>
  <link name="wheel_right_link">
    <visual>
      <origin xyz="0 -7.34641e-10 -0.0002" rpy="-3.141589 0 0"/>
      <geometry>
        <cylinder radius="0.0985" length="0.04"/>
      </geometry>
    </visual>
    <collision>
      <origin xyz="0 -7.34641e-10 -0.0002" rpy="-3.141589 0 0"/>
      <geometry>
        <cylinder radius="0.0985" length="0.04"/>
      </geometry>
    </collision>
  </link>
  <link name="base_sonar_01_link">
  </link>
  <joint name="base_link_base_sonar_01_link_joint" type="fixed">
    <parent link="base_link"/>
    <child link="base_sonar_01_link"/>
    <origin xyz="-0.183 -0.183 0.1728" rpy="0 0 -2.3561852"/>
  </joint>
  <link name="base_sonar_02_link">
  </link>
  <joint name="base_link_base_sonar_02_link_joint" type="fixed">
    <parent link="base_link"/>
    <child link="base_sonar_02_link"/>
    <origin xyz="-0.259 0 0.173" rpy="0 0 -3.1415854"/>
  </joint>
  <link name="base_sonar_03_link">
  </link>
  <joint name="base_link_base_sonar_03_link_joint" type="fixed">
    <parent link="base_link"/>
    <child link="base_sonar_03_link"/>
    <origin xyz="-0.183 0.183 0.173" rpy="0 0 2.3562"/>
  </joint>
  <link name="base_cover_link">
    <visual>
      <origin xyz="0 0 0.043" rpy="-3.141589 0 0"/>
      <geometry>
        <cylinder radius="0.272" length="0.086"/>
      </geometry>
    </visual>
    <collision>
      <origin xyz="0 0 0.043" rpy="-3.141589 0 0"/>
      <geometry>
        <cylinder radius="0.272" length="0.086"/>
      </geometry>
    </collision>
  </link>
  <joint name="base_link_base_cover_link_joint" type="fixed">
    <parent link="base_link"/>
    <child link="base_cover_link"/>
    <origin xyz="0 0 0.03" rpy="0 0 0"/>
  </joint>
  <link name="Hokuyo URG-04LX-UG01">
    <visual>
      <origin xyz="0 -0.0175 0" rpy="0 0 0"/>
      <geometry>
        <box size="0.05 0.07 0.05"/>
      </geometry>
    </visual>
    <collision>
      <origin xyz="0 -0.0175 0" rpy="0 0 0"/>
      <geometry>
        <box size="0.05 0.07 0.05"/>
      </geometry>
    </collision>
  </link>
  <joint name="base_link_Hokuyo URG-04LX-UG01_joint" type="fixed">
    <parent link="base_link"/>
    <child link="Hokuyo URG-04LX-UG01"/>
    <origin xyz="0.202 0 -0.004" rpy="1.5707414 0.00011829441 -1.5707414"/>
  </joint>
  <link name="Torso">
    <visual>
      <origin xyz="0 0 0.275" rpy="0 0 0"/>
      <geometry>
        <box size="0.18 0.2 0.55"/>
      </geometry>
    </visual>
    <collision>
      <origin xyz="0 0 0.275" rpy="0 0 0"/>
      <geometry>
        <box size="0.18 0.2 0.55"/>
      </geometry>
    </collision>
    <visual>
      <origin xyz="0.085 0 0.02" rpy="0 0 0"/>
      <geometry>
        <box size="0.4 0.254 0.04"/>
      </geometry>
    </visual>
    <collision>
      <origin xyz="0.085 0 0.02" rpy="0 0 0"/>
      <geometry>
        <box size="0.4 0.254 0.04"/>
      </geometry>
    </collision>
    <visual>
      <origin xyz="0.001 0 0.05" rpy="0 0 0"/>
      <geometry>
        <box size="0.233 0.26 0.12"/>
      </geometry>
    </visual>
    <collision>
      <origin xyz="0.001 0 0.05" rpy="0 0 0"/>
      <geometry>
        <box size="0.233 0.26 0.12"/>
      </geometry>
    </collision>
  </link>
  <joint name="base_link_Torso_joint" type="fixed">
    <parent link="base_link"/>
    <child link="Torso"/>
    <origin xyz="-0.054 0 0.193" rpy="0 0 0"/>
  </joint>
  <joint name="torso_lift_joint" type="prismatic">
    <parent link="Torso"/>
    <child link="torso_lift_link"/>
    <axis xyz="0 0 1"/>
    <origin xyz="0 0 0.6" rpy="0 0 0"/>
    <limit effort="2000" lower="0" upper="0.35" velocity="0.07"/>
  </joint>
  <link name="torso_lift_link">
    <visual>
      <origin xyz="0.164 0 -0.032" rpy="0 0 0"/>
      <geometry>
        <box size="0.15 0.138 0.074"/>
      </geometry>
    </visual>
    <collision>
      <origin xyz="0.164 0 -0.032" rpy="0 0 0"/>
      <geometry>
        <box size="0.15 0.138 0.074"/>
      </geometry>
    </collision>
    <visual>
      <origin xyz="0.1389 0 -0.0432" rpy="0 -0.43 0"/>
      <geometry>
        <box size="0.12 0.134 0.097"/>
      </geometry>
    </visual>
    <collision>
      <origin xyz="0.1389 0 -0.0432" rpy="0 -0.43 0"/>
      <geometry>
        <box size="0.12 0.134 0.097"/>
      </geometry>
    </collision>
    <visual>
      <origin xyz="-0.016 0 -0.05" rpy="0 0 0"/>
      <geometry>
        <box size="0.291 0.333 0.11"/>
      </geometry>
    </visual>
    <collision>
      <origin xyz="-0.016 0 -0.05" rpy="0 0 0"/>
      <geometry>
        <box size="0.291 0.333 0.11"/>
      </geometry>
    </collision>
    <visual>
      <origin xyz="0.003 0 -0.283" rpy="0 0 0"/>
      <geometry>
        <box size="0.228 0.263 0.358"/>
      </geometry>
    </visual>
    <collision>
      <origin xyz="0.003 0 -0.283" rpy="0 0 0"/>
      <geometry>
        <box size="0.228 0.263 0.358"/>
      </geometry>
    </collision>
  </link>
  <joint name="head_1_joint" type="revolute">
    <parent link="torso_lift_link"/>
    <child link="head_1_link"/>
    <axis xyz="0 0 1"/>
    <limit effort="5.197" lower="-1.24" upper="1.24" velocity="3"/>
    <origin xyz="0.182 0 0" rpy="0 0 0"/>
  </joint>
  <link name="head_1_link">
    <visual>
      <origin xyz="0.01 0 0.097" rpy="1.5707963 0 0"/>
      <geometry>
        <cylinder radius="0.082" length="0.09"/>
      </geometry>
    </visual>
    <collision>
      <origin xyz="0.01 0 0.097" rpy="1.5707963 0 0"/>
      <geometry>
        <cylinder radius="0.082" length="0.09"/>
      </geometry>
    </collision>
    <visual>
      <origin xyz="-0.005 0 0.005" rpy="0 0 0"/>
      <geometry>
        <box size="0.103 0.088 0.103"/>
      </geometry>
    </visual>
    <collision>
      <origin xyz="-0.005 0 0.005" rpy="0 0 0"/>
      <geometry>
        <box size="0.103 0.088 0.103"/>
      </geometry>
    </collision>
  </link>
  <joint name="head_2_joint" type="revolute">
    <parent link="head_1_link"/>
    <child link="head_2_link"/>
    <axis xyz="0 3.6732051e-06 1"/>
    <limit effort="2.77" lower="-0.98" upper="0.79" velocity="3"/>
    <origin xyz="0.005 0 0.098" rpy="1.5708 0 0"/>
  </joint>
  <link name="head_2_link">
    <visual>
      <origin xyz="-0.009 0.0466 0" rpy="0 0 -0.7"/>
      <geometry>
        <box size="0.092 0.132 0.26"/>
      </geometry>
    </visual>
    <collision>
      <origin xyz="-0.009 0.0466 0" rpy="0 0 -0.7"/>
      <geometry>
        <box size="0.092 0.132 0.26"/>
      </geometry>
    </collision>
    <visual>
      <origin xyz="0.008 -0.019 0" rpy="-3.7000516e-06 0 0"/>
      <geometry>
        <cylinder radius="0.03" length="0.132"/>
      </geometry>
    </visual>
    <collision>
      <origin xyz="0.008 -0.019 0" rpy="-3.7000516e-06 0 0"/>
      <geometry>
        <cylinder radius="0.03" length="0.132"/>
      </geometry>
    </collision>
    <visual>
      <origin xyz="0.054 0.06 0" rpy="0 0 0"/>
      <geometry>
        <box size="0.111 0.13 0.16"/>
      </geometry>
    </visual>
    <collision>
      <origin xyz="0.054 0.06 0" rpy="0 0 0"/>
      <geometry>
        <box size="0.111 0.13 0.16"/>
      </geometry>
    </collision>
    <visual>
      <origin xyz="0.053 0.056 -0.068" rpy="1.5707963 -2.7755576e-16 -1.5708"/>
      <geometry>
        <cylinder radius="0.0667" length="0.111"/>
      </geometry>
    </visual>
    <collision>
      <origin xyz="0.053 0.056 -0.068" rpy="1.5707963 -2.7755576e-16 -1.5708"/>
      <geometry>
        <cylinder radius="0.0667" length="0.111"/>
      </geometry>
    </collision>
    <visual>
      <origin xyz="0.053 0.056 0.068" rpy="1.5707963 -2.7755576e-16 -1.5708"/>
      <geometry>
        <cylinder radius="0.0667" length="0.111"/>
      </geometry>
    </visual>
    <collision>
      <origin xyz="0.053 0.056 0.068" rpy="1.5707963 -2.7755576e-16 -1.5708"/>
      <geometry>
        <cylinder radius="0.0667" length="0.111"/>
      </geometry>
    </collision>
  </link>
  <link name="TIAGo front arm_21477">
    <visual>
      <origin xyz="0.026 0.14 -0.232" rpy="0 0 1.5708"/>
      <geometry>
        <box size="0.042 0.094 0.094"/>
      </geometry>
    </visual>
    <collision>
      <origin xyz="0.026 0.14 -0.232" rpy="0 0 1.5708"/>
      <geometry>
        <box size="0.042 0.094 0.094"/>
      </geometry>
    </collision>
    <visual>
      <origin xyz="0.0256 0.1868 -0.2661" rpy="1.6887958e-05 -0.26184443 1.5707794"/>
      <geometry>
        <cylinder radius="0.053" length="0.016"/>
      </geometry>
    </visual>
    <collision>
      <origin xyz="0.0256 0.1868 -0.2661" rpy="1.6887958e-05 -0.26184443 1.5707794"/>
      <geometry>
        <cylinder radius="0.053" length="0.016"/>
      </geometry>
    </collision>
    <visual>
      <origin xyz="0.026 0.19 -0.221" rpy="-3.7000516e-06 0 0"/>
      <geometry>
        <cylinder radius="0.053" length="0.075"/>
      </geometry>
    </visual>
    <collision>
      <origin xyz="0.026 0.19 -0.221" rpy="-3.7000516e-06 0 0"/>
      <geometry>
        <cylinder radius="0.053" length="0.075"/>
      </geometry>
    </collision>
  </link>
  <joint name="torso_lift_link_TIAGo front arm_21477_joint" type="fixed">
    <parent link="torso_lift_link"/>
    <child link="TIAGo front arm_21477"/>
    <origin xyz="-0.037 0.0388 0.0224" rpy="0 0 -1.5708"/>
  </joint>
  <joint name="arm_1_joint" type="revolute">
    <parent link="TIAGo front arm_21477"/>
    <child link="TIAGo front arm_21492"/>
    <axis xyz="0 0 1"/>
    <limit effort="43" lower="0.07" upper="2.68" velocity="1.95"/>
    <origin xyz="0.025 0.194 -0.16" rpy="0 0 0"/>
  </joint>
  <link name="TIAGo front arm_21492">
    <visual>
      <origin xyz="0.0001 0 0.002" rpy="-3.141589 0 0"/>
      <geometry>
        <cylinder radius="0.0522" length="0.052"/>
      </geometry>
    </visual>
    <collision>
      <origin xyz="0.0001 0 0.002" rpy="-3.141589 0 0"/>
      <geometry>
        <cylinder radius="0.0522" length="0.052"/>
      </geometry>
    </collision>
    <visual>
      <origin xyz="0.0331 0.001 0.001" rpy="0 0 0"/>
      <geometry>
        <box size="0.08 0.1044 0.048"/>
      </geometry>
    </visual>
    <collision>
      <origin xyz="0.0331 0.001 0.001" rpy="0 0 0"/>
      <geometry>
        <box size="0.08 0.1044 0.048"/>
      </geometry>
    </collision>
    <visual>
      <origin xyz="0.0721 0.029 -0.023" rpy="0 0 0"/>
      <geometry>
        <box size="0.035 0.09 0.081"/>
      </geometry>
    </visual>
    <collision>
      <origin xyz="0.0721 0.029 -0.023" rpy="0 0 0"/>
      <geometry>
        <box size="0.035 0.09 0.081"/>
      </geometry>
    </collision>
    <visual>
      <origin xyz="0.1251 0.053 -0.042" rpy="1.5707963 0 0"/>
      <geometry>
        <cylinder radius="0.053" length="0.069"/>
      </geometry>
    </visual>
    <collision>
      <origin xyz="0.1251 0.053 -0.042" rpy="1.5707963 0 0"/>
      <geometry>
        <cylinder radius="0.053" length="0.069"/>
      </geometry>
    </collision>
  </link>
  <joint name="arm_2_joint" type="revolute">
    <parent link="TIAGo front arm_21492"/>
    <child link="arm_2_link_21525"/>
    <axis xyz="0 3.6732051e-06 1"/>
    <limit effort="43" lower="-1.5" upper="1.02" velocity="1.95"/>
    <origin xyz="0.1251 0.0195 -0.042" rpy="1.5708 0 0"/>
  </joint>
  <link name="arm_2_link_21525">
    <visual>
      <origin xyz="0.056 5.5098077e-09 -0.0005" rpy="1.5707963 -2.7755576e-16 -1.5708"/>
      <geometry>
        <cylinder radius="0.052" length="0.048"/>
      </geometry>
    </visual>
    <collision>
      <origin xyz="0.056 5.5098077e-09 -0.0005" rpy="1.5707963 -2.7755576e-16 -1.5708"/>
      <geometry>
        <cylinder radius="0.052" length="0.048"/>
      </geometry>
    </collision>
    <visual>
      <origin xyz="0 5.5098077e-09 0.0295" rpy="-3.7000516e-06 0 0"/>
      <geometry>
        <cylinder radius="0.053" length="0.057"/>
      </geometry>
    </visual>
    <collision>
      <origin xyz="0 5.5098077e-09 0.0295" rpy="-3.7000516e-06 0 0"/>
      <geometry>
        <cylinder radius="0.053" length="0.057"/>
      </geometry>
    </collision>
  </link>
  <joint name="arm_3_joint" type="revolute">
    <parent link="arm_2_link_21525"/>
    <child link="arm_3_link_21539"/>
    <axis xyz="-7.801315e-05 -9.5201074e-05 1"/>
    <limit effort="26" lower="-3.46" upper="1.5" velocity="2.35"/>
    <origin xyz="0.0895 5.5098077e-09 -1.0118208e-14" rpy="-1.5708915 9.5201074e-05 1.5707183"/>
  </joint>
  <link name="arm_3_link_21539">
    <visual>
      <origin xyz="-1.7943024e-07 -2.1896247e-07 -0.1037" rpy="-3.7000516e-06 0 0"/>
      <geometry>
        <cylinder radius="0.053" length="0.23"/>
      </geometry>
    </visual>
    <collision>
      <origin xyz="-1.7943024e-07 -2.1896247e-07 -0.1037" rpy="-3.7000516e-06 0 0"/>
      <geometry>
        <cylinder radius="0.053" length="0.23"/>
      </geometry>
    </collision>
    <visual>
      <origin xyz="-0.01690018 0.029999781 -0.2187" rpy="1.5707963 0 0"/>
      <geometry>
        <cylinder radius="0.056" length="0.056"/>
      </geometry>
    </visual>
    <collision>
      <origin xyz="-0.01690018 0.029999781 -0.2187" rpy="1.5707963 0 0"/>
      <geometry>
        <cylinder radius="0.056" length="0.056"/>
      </geometry>
    </collision>
  </link>
  <joint name="arm_4_joint" type="revolute">
    <parent link="arm_3_link_21539"/>
    <child link="arm_4_link_21573"/>
    <axis xyz="2.8276386e-06 -2.8276306e-06 1"/>
    <limit effort="26" lower="-0.32" upper="2.29" velocity="2.35"/>
    <origin xyz="-0.02000018 -0.027000219 -0.2197" rpy="2.356193 -1.5707923 2.356193"/>
  </joint>
  <link name="arm_4_link_21573">
    <visual>
      <origin xyz="0 0.001 -0.002" rpy="-3.141589 0 0"/>
      <geometry>
        <cylinder radius="0.054" length="0.056"/>
      </geometry>
    </visual>
    <collision>
      <origin xyz="0 0.001 -0.002" rpy="-3.141589 0 0"/>
      <geometry>
        <cylinder radius="0.054" length="0.056"/>
      </geometry>
    </collision>
    <visual>
      <origin xyz="-0.093 0.019 0.027" rpy="1.5707963 -2.7755576e-16 -1.5708"/>
      <geometry>
        <cylinder radius="0.052" length="0.191"/>
      </geometry>
    </visual>
    <collision>
      <origin xyz="-0.093 0.019 0.027" rpy="1.5707963 -2.7755576e-16 -1.5708"/>
      <geometry>
        <cylinder radius="0.052" length="0.191"/>
      </geometry>
    </collision>
  </link>
  <joint name="arm_5_joint" type="revolute">
    <parent link="arm_4_link_21573"/>
    <child link="arm_5_link_21607"/>
    <axis xyz="3.6732051e-06 0 1"/>
    <limit effort="3" lower="-2.07" upper="2.07" velocity="1.95"/>
    <origin xyz="-0.162 0.02 0.027" rpy="3.1415927 -1.5707927 3.1415927"/>
  </joint>
  <link name="arm_5_link_21607">
    <visual>
      <origin xyz="0 0 0.04" rpy="3.1407962 0 0"/>
      <geometry>
        <cylinder radius="0.063" length="0.062"/>
      </geometry>
    </visual>
    <collision>
      <origin xyz="0 0 0.04" rpy="3.1407962 0 0"/>
      <geometry>
        <cylinder radius="0.063" length="0.062"/>
      </geometry>
    </collision>
    <visual>
      <origin xyz="0 0 0.099" rpy="3.1407962 0 0"/>
      <geometry>
        <cylinder radius="0.057" length="0.06"/>
      </geometry>
    </visual>
    <collision>
      <origin xyz="0 0 0.099" rpy="3.1407962 0 0"/>
      <geometry>
        <cylinder radius="0.057" length="0.06"/>
      </geometry>
    </collision>
    <visual>
      <origin xyz="0 0 0.156" rpy="3.1407962 0 0"/>
      <geometry>
        <cylinder radius="0.053" length="0.06"/>
      </geometry>
    </visual>
    <collision>
      <origin xyz="0 0 0.156" rpy="3.1407962 0 0"/>
      <geometry>
        <cylinder radius="0.053" length="0.06"/>
      </geometry>
    </collision>
  </link>
  <joint name="arm_6_joint" type="revolute">
    <parent link="arm_5_link_21607"/>
    <child link="arm_6_link_21622"/>
    <axis xyz="2.8276386e-06 -2.8276306e-06 1"/>
    <limit effort="6.6" lower="-1.39" upper="1.39" velocity="1.76"/>
    <origin xyz="0 0 0.15" rpy="2.356193 -1.5707923 2.356193"/>
  </joint>
  <link name="arm_6_link_21622">
    <visual>
      <origin xyz="0.0409 0 0" rpy="1.5707963 -2.7755576e-16 -1.5708"/>
      <geometry>
        <cylinder radius="0.0226" length="0.013"/>
      </geometry>
    </visual>
    <collision>
      <origin xyz="0.0409 0 0" rpy="1.5707963 -2.7755576e-16 -1.5708"/>
      <geometry>
        <cylinder radius="0.0226" length="0.013"/>
      </geometry>
    </collision>
  </link>
  <joint name="arm_7_joint" type="revolute">
    <parent link="arm_6_link_21622"/>
    <child link="arm_7_link_21637"/>
    <axis xyz="-2.8276306e-06 2.8276386e-06 1"/>
    <limit effort="6.6" lower="-2.07" upper="2.07" velocity="1.76"/>
    <origin xyz="0 0 0" rpy="1.5707991 -2.8276386e-06 1.5707991"/>
  </joint>
  <link name="arm_7_link_21637">
    <visual>
      <origin xyz="-1.5551969e-07 1.5552013e-07 0.055" rpy="-3.141589 0 0"/>
      <geometry>
        <cylinder radius="0.0225" length="0.0157"/>
      </geometry>
    </visual>
    <collision>
      <origin xyz="-1.5551969e-07 1.5552013e-07 0.055" rpy="-3.141589 0 0"/>
      <geometry>
        <cylinder radius="0.0225" length="0.0157"/>
      </geometry>
    </collision>
  </link>
  <link name="wrist_ft_tool_link_21649">
    <visual>
      <origin xyz="-1.5551969e-07 1.5552013e-07 0.055" rpy="1.5707963 1.110223e-16 1.57"/>
      <geometry>
        <cylinder radius="0.0253" length="0.011"/>
      </geometry>
    </visual>
    <collision>
      <origin xyz="-1.5551969e-07 1.5552013e-07 0.055" rpy="1.5707963 1.110223e-16 1.57"/>
      <geometry>
        <cylinder radius="0.0253" length="0.011"/>
      </geometry>
    </collision>
  </link>
  <joint name="arm_7_link_21637_wrist_ft_tool_link_21649_joint" type="fixed">
    <parent link="arm_7_link_21637"/>
    <child link="wrist_ft_tool_link_21649"/>
    <origin xyz="-1.5551969e-07 1.5552013e-07 0.067725" rpy="2.356193 -1.5707923 2.356193"/>
  </joint>
  <link name="front_21651">
    <visual>
      <origin xyz="0 0 0" rpy="3.1407962 0 0"/>
      <geometry>
        <cylinder radius="0.0227" length="0.028"/>
      </geometry>
    </visual>
    <collision>
      <origin xyz="0 0 0" rpy="3.1407962 0 0"/>
      <geometry>
        <cylinder radius="0.0227" length="0.028"/>
      </geometry>
    </collision>
    <visual>
      <origin xyz="0.029 -0.01834 -0.046" rpy="0 0 0.59"/>
      <geometry>
        <box size="0.04 0.0217 0.105"/>
      </geometry>
    </visual>
    <collision>
      <origin xyz="0.029 -0.01834 -0.046" rpy="0 0 0.59"/>
      <geometry>
        <box size="0.04 0.0217 0.105"/>
      </geometry>
    </collision>
    <visual>
      <origin xyz="-0.029 0.01834 -0.046" rpy="0 0 0.59"/>
      <geometry>
        <box size="0.04 0.0217 0.105"/>
      </geometry>
    </visual>
    <collision>
      <origin xyz="-0.029 0.01834 -0.046" rpy="0 0 0.59"/>
      <geometry>
        <box size="0.04 0.0217 0.105"/>
      </geometry>
    </collision>
    <visual>
      <origin xyz="0.0172 0.0109 -0.046" rpy="3.1415927 -1.5707927 3.1415927"/>
      <geometry>
        <box size="0.106 0.056 0.071"/>
      </geometry>
    </visual>
    <collision>
      <origin xyz="0.0172 0.0109 -0.046" rpy="3.1415927 -1.5707927 3.1415927"/>
      <geometry>
        <box size="0.106 0.056 0.071"/>
      </geometry>
    </collision>
    <visual>
      <origin xyz="-0.0172 -0.0109 -0.046" rpy="3.1415927 -1.5707927 3.1415927"/>
      <geometry>
        <box size="0.106 0.056 0.071"/>
      </geometry>
    </visual>
    <collision>
      <origin xyz="-0.0172 -0.0109 -0.046" rpy="3.1415927 -1.5707927 3.1415927"/>
      <geometry>
        <box size="0.106 0.056 0.071"/>
      </geometry>
    </collision>
  </link>
  <joint name="wrist_ft_tool_link_21649_front_21651_joint" type="fixed">
    <parent link="wrist_ft_tool_link_21649"/>
    <child link="front_21651"/>
    <origin xyz="0.016 -5.877128e-08 0" rpy="-2.356193 1.5707923 0.78539306"/>
  </joint>
  <joint name="gripper_right_finger_joint" type="prismatic">
    <parent link="front_21651"/>
    <child link="gripper_right_finger_link_22212"/>
    <axis xyz="1 0 0"/>
    <origin xyz="0 0 0" rpy="0 0 0"/>
    <limit effort="16" lower="0" upper="0.045" velocity="0.05"/>
  </joint>
  <link name="gripper_right_finger_link_22212">
    <visual>
      <origin xyz="0.004 0 -0.1741" rpy="0 0 0"/>
      <geometry>
        <box size="0.0076 0.05091 0.08982"/>
      </geometry>
    </visual>
    <collision>
      <origin xyz="0.004 0 -0.1741" rpy="0 0 0"/>
      <geometry>
        <box size="0.0076 0.05091 0.08982"/>
      </geometry>
    </collision>
    <visual>
      <origin xyz="0.0049 0.0153 -0.1208" rpy="0 0 0"/>
      <geometry>
        <box size="0.0055 0.0295 0.018"/>
      </geometry>
    </visual>
    <collision>
      <origin xyz="0.0049 0.0153 -0.1208" rpy="0 0 0"/>
      <geometry>
        <box size="0.0055 0.0295 0.018"/>
      </geometry>
    </collision>
    <visual>
      <origin xyz="-0.0085 0.0156 -0.1048" rpy="0 0 0"/>
      <geometry>
        <box size="0.03213 0.02959 0.01487"/>
      </geometry>
    </visual>
    <collision>
      <origin xyz="-0.0085 0.0156 -0.1048" rpy="0 0 0"/>
      <geometry>
        <box size="0.03213 0.02959 0.01487"/>
      </geometry>
    </collision>
  </link>
  <joint name="gripper_left_finger_joint" type="prismatic">
    <parent link="front_21651"/>
    <child link="gripper_left_finger_link_22179"/>
    <axis xyz="1 9.265359e-05 0"/>
    <origin xyz="0 0 0" rpy="0 0 3.1415"/>
    <limit effort="16" lower="0" upper="0.045" velocity="0.05"/>
  </joint>
  <link name="gripper_left_finger_link_22179">
    <visual>
      <origin xyz="0.004 0 -0.1741" rpy="0 0 0"/>
      <geometry>
        <box size="0.0076 0.05091 0.08982"/>
      </geometry>
    </visual>
    <collision>
      <origin xyz="0.004 0 -0.1741" rpy="0 0 0"/>
      <geometry>
        <box size="0.0076 0.05091 0.08982"/>
      </geometry>
    </collision>
    <visual>
      <origin xyz="0.0049 0.0153 -0.1208" rpy="0 0 0"/>
      <geometry>
        <box size="0.0055 0.0295 0.018"/>
      </geometry>
    </visual>
    <collision>
      <origin xyz="0.0049 0.0153 -0.1208" rpy="0 0 0"/>
      <geometry>
        <box size="0.0055 0.0295 0.018"/>
      </geometry>
    </collision>
    <visual>
      <origin xyz="-0.0085 0.0156 -0.1048" rpy="0 0 0"/>
      <geometry>
        <box size="0.03213 0.02959 0.01487"/>
      </geometry>
    </visual>
    <collision>
      <origin xyz="-0.0085 0.0156 -0.1048" rpy="0 0 0"/>
      <geometry>
        <box size="0.03213 0.02959 0.01487"/>
      </geometry>
    </collision>
  </link>
  <link name="cap screw(19)_22151">
  </link>
  <joint name="front_21651_cap screw(19)_22151_joint" type="fixed">
    <parent link="front_21651"/>
    <child link="cap screw(19)_22151"/>
    <origin xyz="0.0415 -0.0029 -0.0004" rpy="3.14159 0 0"/>
  </joint>
  <link name="cap screw(18)_22127">
  </link>
  <joint name="front_21651_cap screw(18)_22127_joint" type="fixed">
    <parent link="front_21651"/>
    <child link="cap screw(18)_22127"/>
    <origin xyz="-0.0415 0.0029 -0.0004" rpy="3.14159 0 0"/>
  </joint>
  <link name="cap screw(17)_22103">
  </link>
  <joint name="front_21651_cap screw(17)_22103_joint" type="fixed">
    <parent link="front_21651"/>
    <child link="cap screw(17)_22103"/>
    <origin xyz="0.0433 0.0315 0.0026" rpy="3.14159 0 0"/>
  </joint>
  <link name="cap screw(16)_22079">
  </link>
  <joint name="front_21651_cap screw(16)_22079_joint" type="fixed">
    <parent link="front_21651"/>
    <child link="cap screw(16)_22079"/>
    <origin xyz="-0.0433 -0.0315 0.0026" rpy="3.14159 0 0"/>
  </joint>
  <link name="cap screw(15)_22055">
  </link>
  <joint name="front_21651_cap screw(15)_22055_joint" type="fixed">
    <parent link="front_21651"/>
    <child link="cap screw(15)_22055"/>
    <origin xyz="0 0.033 0.0026" rpy="3.14159 0 0"/>
  </joint>
  <link name="cap screw(14)_22031">
  </link>
  <joint name="front_21651_cap screw(14)_22031_joint" type="fixed">
    <parent link="front_21651"/>
    <child link="cap screw(14)_22031"/>
    <origin xyz="0 -0.033 0.0026" rpy="3.14159 0 0"/>
  </joint>
  <link name="cap screw(13)_22007">
  </link>
  <joint name="front_21651_cap screw(13)_22007_joint" type="fixed">
    <parent link="front_21651"/>
    <child link="cap screw(13)_22007"/>
    <origin xyz="0.0426 -0.0094 -0.09448" rpy="0 0 0"/>
  </joint>
  <link name="cap screw(12)_21983">
  </link>
  <joint name="front_21651_cap screw(12)_21983_joint" type="fixed">
    <parent link="front_21651"/>
    <child link="cap screw(12)_21983"/>
    <origin xyz="-0.0425 0.0094 -0.0945" rpy="0 0 0"/>
  </joint>
  <link name="cap screw(11)_21959">
  </link>
  <joint name="front_21651_cap screw(11)_21959_joint" type="fixed">
    <parent link="front_21651"/>
    <child link="cap screw(11)_21959"/>
    <origin xyz="-0.0477 -0.008 -0.0108" rpy="3.1415927 1.5707927 3.1415927"/>
  </joint>
  <link name="cap screw(10)_21935">
  </link>
  <joint name="front_21651_cap screw(10)_21935_joint" type="fixed">
    <parent link="front_21651"/>
    <child link="cap screw(10)_21935"/>
    <origin xyz="-0.0477 -0.008 -0.043" rpy="3.1415927 1.5707927 3.1415927"/>
  </joint>
  <link name="cap screw(9)_21911">
  </link>
  <joint name="front_21651_cap screw(9)_21911_joint" type="fixed">
    <parent link="front_21651"/>
    <child link="cap screw(9)_21911"/>
    <origin xyz="-0.0477 -0.008 -0.075" rpy="3.1415927 1.5707927 3.1415927"/>
  </joint>
  <link name="cap screw(8)_21887">
  </link>
  <joint name="front_21651_cap screw(8)_21887_joint" type="fixed">
    <parent link="front_21651"/>
    <child link="cap screw(8)_21887"/>
    <origin xyz="-0.0477 0.008 -0.075" rpy="3.1415927 1.5707927 3.1415927"/>
  </joint>
  <link name="cap screw(7)_21863">
  </link>
  <joint name="front_21651_cap screw(7)_21863_joint" type="fixed">
    <parent link="front_21651"/>
    <child link="cap screw(7)_21863"/>
    <origin xyz="-0.0477 0.008 -0.043" rpy="3.1415927 1.5707927 3.1415927"/>
  </joint>
  <link name="cap screw(6)_21839">
  </link>
  <joint name="front_21651_cap screw(6)_21839_joint" type="fixed">
    <parent link="front_21651"/>
    <child link="cap screw(6)_21839"/>
    <origin xyz="-0.0477 0.008 -0.0108" rpy="3.1415927 1.5707927 3.1415927"/>
  </joint>
  <link name="cap screw(5)_21815">
  </link>
  <joint name="front_21651_cap screw(5)_21815_joint" type="fixed">
    <parent link="front_21651"/>
    <child link="cap screw(5)_21815"/>
    <origin xyz="0.0477 -0.008 -0.0108" rpy="3.1415927 -1.5707927 3.1415927"/>
  </joint>
  <link name="cap screw(4)_21791">
  </link>
  <joint name="front_21651_cap screw(4)_21791_joint" type="fixed">
    <parent link="front_21651"/>
    <child link="cap screw(4)_21791"/>
    <origin xyz="0.0477 -0.008 -0.043" rpy="3.1415927 -1.5707927 3.1415927"/>
  </joint>
  <link name="cap screw(3)_21767">
  </link>
  <joint name="front_21651_cap screw(3)_21767_joint" type="fixed">
    <parent link="front_21651"/>
    <child link="cap screw(3)_21767"/>
    <origin xyz="0.0477 -0.008 -0.075" rpy="3.1415927 -1.5707927 3.1415927"/>
  </joint>
  <link name="cap screw(2)_21743">
  </link>
  <joint name="front_21651_cap screw(2)_21743_joint" type="fixed">
    <parent link="front_21651"/>
    <child link="cap screw(2)_21743"/>
    <origin xyz="0.0477 0.008 -0.075" rpy="3.1415927 -1.5707927 3.1415927"/>
  </joint>
  <link name="cap screw(1)_21719">
  </link>
  <joint name="front_21651_cap screw(1)_21719_joint" type="fixed">
    <parent link="front_21651"/>
    <child link="cap screw(1)_21719"/>
    <origin xyz="0.0477 0.008 -0.043" rpy="3.1415927 -1.5707927 3.1415927"/>
  </joint>
  <link name="cap screw_21695">
  </link>
  <joint name="front_21651_cap screw_21695_joint" type="fixed">
    <parent link="front_21651"/>
    <child link="cap screw_21695"/>
    <origin xyz="0.0477 0.008 -0.0108" rpy="3.1415927 -1.5707927 3.1415927"/>
  </joint>
</robot>
